<?xml version="1.0" encoding="utf-8"?>
<!-- =================================================================================== -->
<!-- |    This document was autogenerated by xacro from /home/jslesing/workspace/src/robik_description/urdf/robik.urdf.xacro | -->
<!-- |    EDITING THIS FILE BY HAND IS NOT RECOMMENDED                                 | -->
<!-- =================================================================================== -->
<!-- (x/red +dopredu -dozadu) (y/green -levo +vpravo) (z/blue -dolu +nahoru) -->
<robot name="robik">
  <!-- materials -->
  <material name="clear_plastic">
    <color rgba="0.81 0.81 0.81 0.5"/>
  </material>
  <material name="alum">
    <color rgba="0.81 0.88 0.91 1"/>
  </material>
  <material name="wood">
    <color rgba="1 0.81 0.4 1"/>
  </material>
  <material name="jetson">
    <texture filename="package://robik_description/materials/jetson.jpg"/>
  </material>
  <!-- base -->
  <link name="base_link">
    <visual name="base">
      <origin rpy="0 0 0" xyz="0 0 0.065"/>
      <geometry>
        <mesh filename="package://robik_description/meshes/base-binary.stl" scale="1.0 1.0 1.0"/>
      </geometry>
      <material name="clear_plastic"/>
    </visual>
    <collision>
      <origin rpy="0 0 0" xyz="-0.06 0 0.065"/>
      <geometry>
        <box size="0.365 0.352 0.006"/>
      </geometry>
    </collision>
    <collision>
      <origin rpy="0 0 0" xyz="0.115 0 0.071"/>
      <geometry>
        <box size="0.01 0.352 0.01"/>
      </geometry>
    </collision>
    <visual name="caster">
      <origin rpy="0 0 0" xyz="-0.20 0 0.0325"/>
      <geometry>
        <box size="0.05 0.01 0.065"/>
      </geometry>
      <material name="clear_plastic"/>
    </visual>
    <collision>
      <origin rpy="0 0 0" xyz="-0.20 0 0.0325"/>
      <geometry>
        <box size="0.05 0.01 0.065"/>
      </geometry>
    </collision>
    <visual name="{$name_tmpl}_visual">
      <origin rpy="0 0 0" xyz="-0.225 0.07 0.3075"/>
      <geometry>
        <box size="0.01 0.01 0.485"/>
      </geometry>
      <material name="alum"/>
    </visual>
    <collision>
      <origin rpy="0 0 0" xyz="-0.225 0.07 0.3075"/>
      <geometry>
        <box size="0.01 0.01 0.485"/>
      </geometry>
    </collision>
    <visual name="{$name_tmpl}_visual">
      <origin rpy="0 0 0" xyz="-0.225 -0.07 0.3075"/>
      <geometry>
        <box size="0.01 0.01 0.485"/>
      </geometry>
      <material name="alum"/>
    </visual>
    <collision>
      <origin rpy="0 0 0" xyz="-0.225 -0.07 0.3075"/>
      <geometry>
        <box size="0.01 0.01 0.485"/>
      </geometry>
    </collision>
    <visual name="head_base">
      <origin rpy="0 0 0" xyz="-0.225 0 0.55"/>
      <geometry>
        <box size="0.06 0.22 0.02"/>
      </geometry>
      <material name="wood"/>
    </visual>
    <collision>
      <origin rpy="0 0 0" xyz="-0.225 0 0.55"/>
      <geometry>
        <box size="0.06 0.22 0.02"/>
      </geometry>
    </collision>
    <visual name="jetson">
      <origin rpy="0 0 0" xyz="-0.22 0 0.2175"/>
      <geometry>
        <box size="0.006 0.125 0.125"/>
      </geometry>
      <material name="jetson"/>
    </visual>
    <collision>
      <origin rpy="0 0 0" xyz="-0.22 0 0.2175"/>
      <geometry>
        <box size="0.006 0.125 0.125"/>
      </geometry>
    </collision>
    <visual name="jetson_cover">
      <origin rpy="0 0 0" xyz="-0.205 0 0.205"/>
      <geometry>
        <box size="0.006 0.22 0.15"/>
      </geometry>
      <material name="clear_plastic"/>
    </visual>
    <collision>
      <origin rpy="0 0 0" xyz="-0.205 0 0.205"/>
      <geometry>
        <box size="0.006 0.22 0.15"/>
      </geometry>
    </collision>
    <visual name="arduino_cover">
      <origin rpy="0 0 0" xyz="-0.125 0 0.12"/>
      <geometry>
        <box size="0.17 0.25 0.006"/>
      </geometry>
      <material name="clear_plastic"/>
    </visual>
    <collision>
      <origin rpy="0 0 0" xyz="-0.125 0 0.12"/>
      <geometry>
        <box size="0.17 0.25 0.006"/>
      </geometry>
    </collision>
    <visual name="{$name_tmpl}_visual">
      <origin rpy="-0.1745 0 0" xyz="-0.225 0.12 0.325"/>
      <geometry>
        <box size="0.01 0.01 0.13"/>
      </geometry>
      <material name="wheel"/>
    </visual>
    <collision>
      <origin rpy="-0.1745 0 0" xyz="-0.225 0.12 0.325"/>
      <geometry>
        <box size="0.01 0.01 0.13"/>
      </geometry>
    </collision>
    <visual name="{$name_tmpl}_visual">
      <origin rpy="0.1745 0 0" xyz="-0.225 -0.12 0.325"/>
      <geometry>
        <box size="0.01 0.01 0.13"/>
      </geometry>
      <material name="wheel"/>
    </visual>
    <collision>
      <origin rpy="0.1745 0 0" xyz="-0.225 -0.12 0.325"/>
      <geometry>
        <box size="0.01 0.01 0.13"/>
      </geometry>
    </collision>
  </link>
  <!--
	<link name="base_footprint" />
	<link name="base_stabilized" />

	<joint name="base_footprint_joint" type="fixed">
		<origin xyz="0 0 0" rpy="0 0 0" />
		<parent link="base_footprint"/>
		<child link="base_stabilized"/>
	</joint>

	<joint name="base_stabilized_joint" type="fixed">
		<origin xyz="0 0 0" rpy="0 0 0" />
		<parent link="base_stabilized"/>
		<child link="base_link"/>
	</joint>
-->
  <link name="left_wheel">
    <visual>
      <origin rpy="0 1.57079632679 1.57079632679" xyz="0 0 0"/>
      <geometry>
        <cylinder length="0.04" radius="0.05"/>
      </geometry>
      <material name="black_wheel">
        <color rgba="0.1 0.1 0.1 1"/>
      </material>
    </visual>
  </link>
  <link name="right_wheel">
    <visual>
      <origin rpy="0 1.57079632679 1.57079632679" xyz="0 0 0"/>
      <geometry>
        <cylinder length="0.04" radius="0.05"/>
      </geometry>
      <material name="black_wheel">
        <color rgba="0.1 0.1 0.1 1"/>
      </material>
    </visual>
  </link>
  <joint name="wheel_left_joint" type="continuous">
    <origin rpy="0 0 0" xyz="0 0.15 0.05"/>
    <parent link="base_link"/>
    <child link="left_wheel"/>
  </joint>
  <joint name="wheel_right_joint" type="continuous">
    <origin rpy="0 0 0" xyz="0 -0.15 0.05"/>
    <parent link="base_link"/>
    <child link="right_wheel"/>
  </joint>
  <!--  <xacro:include filename="$(find robik_description)/urdf/kinect_gazebo.urdf.xacro"/> -->
  <joint name="camera_rgb_joint" type="fixed">
    <origin rpy="0 0.262 0" xyz="-0.19 0 0.59"/>
    <parent link="base_link"/>
    <child link="camera_rgb_frame"/>
  </joint>
  <link name="camera_rgb_frame">
    <inertial>
      <mass value="0.001"/>
      <origin xyz="0 0 0"/>
      <inertia ixx="0.0001" ixy="0.0" ixz="0.0" iyy="0.0001" iyz="0.0" izz="0.0001"/>
    </inertial>
  </link>
  <joint name="camera_rgb_optical_joint" type="fixed">
    <origin rpy="-1.57079632679 0 -1.57079632679" xyz="0 0 0"/>
    <parent link="camera_rgb_frame"/>
    <child link="camera_rgb_optical_frame"/>
  </joint>
  <link name="camera_rgb_optical_frame">
    <inertial>
      <mass value="0.001"/>
      <origin xyz="0 0 0"/>
      <inertia ixx="0.0001" ixy="0.0" ixz="0.0" iyy="0.0001" iyz="0.0" izz="0.0001"/>
    </inertial>
  </link>
  <joint name="camera_joint" type="fixed">
    <origin rpy="0 0 0" xyz="-0.031 0 -0.016"/>
    <parent link="camera_rgb_frame"/>
    <child link="camera_link"/>
  </joint>
  <link name="camera_link">
    <visual>
      <origin rpy="0 0 1.57079632679" xyz="0 0 0"/>
      <geometry>
        <mesh filename="package://robik/model/v3/meshes/kinect.dae"/>
      </geometry>
    </visual>
    <collision>
      <origin rpy="0 0 0" xyz="0.0 0.0 0.0"/>
      <geometry>
        <box size="0.07271 0.27794 0.073"/>
      </geometry>
    </collision>
    <inertial>
      <mass value="0.001"/>
      <origin xyz="0 0 0"/>
      <inertia ixx="0.0001" ixy="0.0" ixz="0.0" iyy="0.0001" iyz="0.0" izz="0.0001"/>
    </inertial>
  </link>
  <!-- The fixed joints & links below are usually published by static_transformers launched by the OpenNi launch
          files. However, for Gazebo simulation we need them, so we add them here.
          (Hence, don't publish them additionally!) -->
  <joint name="camera_depth_joint" type="fixed">
    <origin rpy="0 0 0" xyz="0 0 0"/>
    <parent link="camera_rgb_frame"/>
    <child link="camera_depth_frame"/>
  </joint>
  <link name="camera_depth_frame">
    <inertial>
      <mass value="0.001"/>
      <origin xyz="0 0 0"/>
      <inertia ixx="0.0001" ixy="0.0" ixz="0.0" iyy="0.0001" iyz="0.0" izz="0.0001"/>
    </inertial>
  </link>
  <joint name="camera_depth_optical_joint" type="fixed">
    <origin rpy="-1.57079632679 0 -1.57079632679" xyz="0 0 0"/>
    <parent link="camera_depth_frame"/>
    <child link="camera_depth_optical_frame"/>
  </joint>
  <link name="camera_depth_optical_frame">
    <inertial>
      <mass value="0.001"/>
      <origin xyz="0 0 0"/>
      <inertia ixx="0.0001" ixy="0.0" ixz="0.0" iyy="0.0001" iyz="0.0" izz="0.0001"/>
    </inertial>
  </link>
  <!-- Kinect sensor for simulation -->
  <turtlebot_sim_3dsensor/>
  <link name="base_scan_link"/>
  <joint name="base_scan_joint" type="fixed">
    <parent link="base_link"/>
    <child link="base_scan_link"/>
    <origin rpy="0 0 0" xyz="-0.15 0 0.15"/>
  </joint>
  <!-- arm -->
  <link name="yaw_link">
    <visual>
      <origin rpy="0 0 0" xyz="0 0 0.03"/>
      <geometry>
        <box size="0.045 0.04 0.06"/>
      </geometry>
      <material name="wood"/>
    </visual>
  </link>
  <joint name="yaw_joint" type="revolute">
    <parent link="base_link"/>
    <child link="yaw_link"/>
    <origin rpy="0 0 0" xyz="0.075 -0.08 0.068"/>
    <axis xyz="0 0 -1"/>
    <limit effort="1000" lower="-1.8675023" upper="1.099557429" velocity="1"/>
  </joint>
  <link name="shoulder_link">
    <visual>
      <origin rpy="0 0 0" xyz="0 0.0675 0"/>
      <geometry>
        <box size="0.04 0.135 0.02"/>
      </geometry>
      <material name="wood">
        <color rgba="0 1.0 1.0 1.0"/>
      </material>
    </visual>
  </link>
  <joint name="shoulder_joint" type="revolute">
    <parent link="yaw_link"/>
    <child link="shoulder_link"/>
    <origin rpy="0 0 -1.570796327" xyz="0.0 0 0.06"/>
    <axis xyz="1 0 0"/>
    <limit effort="1000" lower="0" upper="2.094395102" velocity="1"/>
  </joint>
  <link name="elbow_link">
    <visual>
      <origin rpy="0 0 0" xyz="0 0.0325 0"/>
      <geometry>
        <box size="0.04 0.065 0.02"/>
      </geometry>
      <material name="wood">
        <color rgba="0 1.0 1.0 1.0"/>
      </material>
    </visual>
  </link>
  <joint name="elbow_joint" type="revolute">
    <parent link="shoulder_link"/>
    <child link="elbow_link"/>
    <origin rpy="0 0 0" xyz="0 0.135 0"/>
    <axis xyz="1 0 0"/>
    <limit effort="1000" lower="-1.919862177" upper="0.6981317008" velocity="1"/>
  </joint>
  <link name="roll_link">
    <visual>
      <geometry>
        <box size="0.03 0.003 0.04"/>
      </geometry>
      <material name="wood">
        <color rgba="0 1.0 1.0 1.0"/>
      </material>
    </visual>
  </link>
  <joint name="roll_joint" type="revolute">
    <parent link="elbow_link"/>
    <child link="roll_link"/>
    <origin rpy="0 0 0" xyz="0 0.065 0"/>
    <axis xyz="0 1 0"/>
    <limit effort="1000" lower="-1.570796327" upper="1.570796327" velocity="1"/>
  </joint>
  <link name="clamp_link">
    <visual>
      <origin rpy="0 0 0" xyz="0 0.057 0"/>
      <geometry>
        <box size="0.02 0.09 0.01"/>
      </geometry>
      <material name="alum">
        <color rgba="0 1.0 1.0 1.0"/>
      </material>
    </visual>
  </link>
  <joint name="clamp_joint" type="revolute">
    <parent link="roll_link"/>
    <child link="clamp_link"/>
    <origin rpy="0 0 0" xyz="0 0.001 -0.005"/>
    <axis xyz="-1 0 0"/>
    <limit effort="1000" lower="0" upper="0.6981317008" velocity="1"/>
    <!--<mimic joint="clamp_joint" multiplier="-1" offset="0"/>-->
  </joint>
</robot>
