<?xml version='1.0'?>
<sdf version='1.5'>
  <model name='robik_v3'>
    <static>false</static>

    <link name='base_link'>
      <pose>0 0 0.065 0 0 0</pose>
      <visual name='base_visual'>
        <geometry>
          <mesh>
            <uri>/home/honza/openscad/base.stl</uri>
            <scale>1 1 1</scale>
          </mesh>
        </geometry>
	<material>
	  <ambient>0.81 0.81 0.81 0.5</ambient>
	  <diffuse>0.81 0.81 0.81 0.5</diffuse>
	</material>
      </visual>
      <collision name='base_collision'>
	<pose>-0.06 0 0 0 0 0</pose>
        <geometry>
          <box>
            <size>0.365 0.352 0.006</size>
          </box>
        </geometry>
      </collision>

      <visual name='caster_visual'>
	<pose>-0.20 0 -0.0325 0 0 0</pose>
        <geometry>
	  <box>
	    <size>0.01 0.01 0.065</size>
	  </box>
        </geometry>
      </visual>
      <collision name='caster_collision'>
	<pose>-0.20 0 -0.0325 0 0 0</pose>
        <geometry>
          <box>
            <size>0.01 0.01 0.065</size>
          </box>
        </geometry>
          <surface>
            <friction>
              <ode>
                <mu>0</mu>
                <mu2>0</mu2>
                <slip1>1.0</slip1>
                <slip2>1.0</slip2>
              </ode>
            </friction>
          </surface>
      </collision>

      <visual name='left_backbone_visual'>
	<pose>-0.225 0.07 0.2425 0 0 0</pose>
        <geometry>
	  <box>
	    <size>0.01 0.01 0.485</size>
	  </box>
        </geometry>
	<material>
	  <ambient>0.81 0.88 0.91 1</ambient>
	  <diffuse>0.81 0.88 0.91 1</diffuse>
	</material>
      </visual>
      <collision name='left_backbone_collision'>
	<pose>-0.225 0.07 0.2425 0 0 0</pose>
        <geometry>
          <box>
            <size>0.01 0.01 0.485</size>
          </box>
        </geometry>
      </collision>

      <visual name='right_backbone_visual'>
	<pose>-0.225 -0.07 0.2425 0 0 0</pose>
        <geometry>
	  <box>
	    <size>0.01 0.01 0.485</size>
	  </box>
        </geometry>
	<material>
	  <ambient>0.81 0.88 0.91 1</ambient>
	  <diffuse>0.81 0.88 0.91 1</diffuse>
	</material>
      </visual>
      <collision name='right_backbone_collision'>
	<pose>-0.225 -0.07 0.2425 0 0 0</pose>
        <geometry>
          <box>
            <size>0.01 0.01 0.485</size>
          </box>
        </geometry>
      </collision>

      <visual name='head_base_visual'>
	<pose>-0.20 0 0.485 0 0 0</pose>
        <geometry>
	  <box>
	    <size>0.06 0.22 0.02</size>
	  </box>
        </geometry>
	<material>
	  <ambient>1 0.81 0.4 1</ambient>
	  <diffuse>1 0.81 0.4 1</diffuse>
	</material>
      </visual>
      <collision name='head_base_collision'>
	<pose>-0.20 0 0.485 0 0 0</pose>
        <geometry>
          <box>
            <size>0.06 0.22 0.02</size>
          </box>
        </geometry>
      </collision>

      <visual name='jetson_visual'>
	<pose>-0.22 0 0.1525 0 0 0</pose>
        <geometry>
	  <box>
	    <size>0.006 0.125 0.125</size>
	  </box>
        </geometry>
	<material>
           <script>
              <uri>model://robik_v3/materials/scripts</uri>
              <uri>model://robik_v3/materials/textures</uri>
              <name>Jetson/FrontSide</name>
           </script>
	</material>
      </visual>
      <collision name='jetson_collision'>
	<pose>-0.22 0 0.1525 0 0 0</pose>
        <geometry>
          <box>
            <size>0.006 0.125 0.125</size>
          </box>
        </geometry>
      </collision>

      <visual name='jetson_cover_visual'>
	<pose>-0.205 0 0.14 0 0 0</pose>
        <geometry>
	  <box>
	    <size>0.006 0.22 0.15</size>
	  </box>
        </geometry>
	<material>
	  <ambient>0.81 0.81 0.81 0.5</ambient>
	  <diffuse>0.81 0.81 0.81 0.5</diffuse>
	</material>
      </visual>
      <collision name='jetson_cover_collision'>
	<pose>-0.205 0 0.14 0 0 0</pose>
        <geometry>
          <box>
            <size>0.006 0.22 0.15</size>
          </box>
        </geometry>
      </collision>

      <visual name='arduino_cover_visual'>
	<pose>-0.125 0 0.055 0 0 0</pose>
        <geometry>
	  <box>
	    <size>0.17 0.25 0.006</size>
	  </box>
        </geometry>
	<material>
	  <ambient>0.81 0.81 0.81 0.5</ambient>
	  <diffuse>0.81 0.81 0.81 0.5</diffuse>
	</material>
      </visual>
      <collision name='arduino_cover_collision'>
	<pose>-0.125 0 0.055 0 0 0</pose>
        <geometry>
          <box>
            <size>0.17 0.25 0.006</size>
          </box>
        </geometry>
      </collision>

      <visual name='left_antenna_visual'>
	<pose>-0.225 0.12 0.26 -0.1745 0 0</pose>
        <geometry>
	  <box>
	    <size>0.01 0.01 0.13</size>
	  </box>
        </geometry>
	<material>
	  <ambient>0.1 0.1 0.1 1</ambient>
	  <diffuse>0.1 0.1 0.1 1</diffuse>
	</material>
      </visual>
      <collision name='left_antenna_collision'>
	<pose>-0.225 0.12 0.26 -0.1745 0 0</pose>
        <geometry>
          <box>
            <size>0.01 0.01 0.13</size>
          </box>
        </geometry>
      </collision>

      <visual name='right_antenna_visual'>
	<pose>-0.225 -0.12 0.26 0.1745 0 0</pose>
        <geometry>
	  <box>
	    <size>0.01 0.01 0.13</size>
	  </box>
        </geometry>
	<material>
	  <ambient>0.1 0.1 0.1 1</ambient>
	  <diffuse>0.1 0.1 0.1 1</diffuse>
	</material>
      </visual>
      <collision name='right_antenna_collision'>
	<pose>-0.225 -0.12 0.26 0.1745 0 0</pose>
        <geometry>
          <box>
            <size>0.01 0.01 0.13</size>
          </box>
        </geometry>
      </collision>
    </link>

    <link name='wheel_left'>
      <pose>0 0.15 0.05 0 1.570796 1.570796</pose>
      <visual name='visual'>
        <geometry>
          <cylinder>
            <radius>0.05</radius>
            <length>0.04</length>
          </cylinder>
        </geometry>
	<material>
	  <ambient>0.1 0.1 0.1 1</ambient>
	  <diffuse>0.1 0.1 0.1 1</diffuse>
	</material>
      </visual>
      <collision name='collision'>
        <geometry>
          <cylinder>
            <radius>0.05</radius>
            <length>0.04</length>
          </cylinder>
        </geometry>
      </collision>
    </link>

    <link name='wheel_right'>
      <pose>0 -0.15 0.05 0 1.57076 1.57076</pose>
      <visual name='visual'>
        <geometry>
          <cylinder>
            <radius>0.05</radius>
            <length>0.04</length>
          </cylinder>
        </geometry>
	<material>
	  <ambient>0.1 0.1 0.1 1</ambient>
	  <diffuse>0.1 0.1 0.1 1</diffuse>
	</material>
      </visual>
      <collision name='collision'>
        <geometry>
          <cylinder>
            <radius>0.05</radius>
            <length>0.04</length>
          </cylinder>
        </geometry>
      </collision>
    </link>

    <joint name='wheel_left_joint' type='revolute'>
      <parent>base_link</parent>
      <child>wheel_left</child>
      <pose>0 0 0  0 0 0</pose>
      <axis>
        <xyz>0 1 0</xyz>
	<use_parent_model_frame>true</use_parent_model_frame>
      </axis>
    </joint>

    <joint name='wheel_right_joint' type='revolute'>
      <parent>base_link</parent>
      <child>wheel_right</child>
      <pose>0 0 0  0 0 0</pose>
      <axis>
        <xyz>0 1 0</xyz>
	<use_parent_model_frame>true</use_parent_model_frame>
      </axis>
    </joint>

    <include>
       <!-- Folder name of the model -->
       <uri>model://kinect</uri>
       <name>kinect</name>
       <pose>-0.17 0 0.595   0 0.262 0</pose>
     </include>
    <joint name='kinect_joint' type='fixed'>
      <parent>base_link</parent>
      <child>kinect::link</child>
      <pose>0 0 0  0 0 0</pose>
    </joint>


    <!-- ARM -->

    <link name="yaw_link">
      <visual name="yaw_visual">
	<pose>0.075 -0.08 0.098  0 0 0</pose>
	<geometry>
	  <box>
	    <size>0.045 0.04 0.06</size>
	  </box>
	</geometry>
	<material>
	  <ambient>1 0.81 0.4 1</ambient>
	  <diffuse>1 0.81 0.4 1</diffuse>
	</material>
      </visual>
      <collision name="yaw_collision">
	<pose>0.075 -0.08 0.098  0 0 0</pose>
	<geometry>
	  <box>
	    <size>0.045 0.04 0.06</size>
	  </box>
	</geometry>
      </collision>
    </link>

    <joint name="yaw_joint" type="revolute">
      <parent>base_link</parent>
      <child>yaw_link</child>
      <pose>0.075 -0.08 0.068  0 0 0</pose>
      <axis>
        <xyz>0 0 1</xyz>
	<limit>
	  <lower>-1.8675023</lower>
	  <upper>1.099557429</upper>
	  <effort>1000</effort>
	  <velocity>1</velocity>
	</limit>
	<use_parent_model_frame>true</use_parent_model_frame>
      </axis>
    </joint>


    <link name="shoulder_link">
      <visual name="shoulder_visual">
	<pose>0 0.0675 0  0 0 0</pose>
	<geometry>
	  <box>
	    <size>0.04 0.135 0.02</size>
	  </box>
	</geometry>
	<material>
	  <ambient>1 0.81 0.4 1</ambient>
	  <diffuse>1 0.81 0.4 1</diffuse>
	</material>
      </visual>
      <collision name="shoulder_collision">
	<pose>0 0.0675 0  0 0 0</pose>
	<geometry>
	  <box>
	    <size>0.04 0.135 0.02</size>
	  </box>
	</geometry>
      </collision>
    </link>

    <joint name="shoulder_joint" type="revolute">
      <parent>yaw_link</parent>
      <child>shoulder_link</child>
      <pose>0 0.0675 0  0 0 0</pose>
      <axis>
	<xyz>1 0 0</xyz>
	<limit>
	  <lower>0</lower>
	  <upper>2.094395102</upper>
	  <effort>1000</effort>
	  <velocity>1</velocity>
	</limit>
	<use_parent_model_frame>true</use_parent_model_frame>
      </axis>
    </joint>

<!--
    <link name="elbow_link">
      <visual name="elbow_visual">
	<pose>0 0.0325 0  0 0 0</pose>
	<geometry>
	  <box>
	    <size>0.04 0.065 0.02</size>
	  </box>
	</geometry>
	<material>
	  <ambient>1 0.81 0.4 1</ambient>
	  <diffuse>1 0.81 0.4 1</diffuse>
	</material>
      </visual>
      <collision name="elbow_collision">
	<geometry>
	  <box>
	    <size>0.04 0.065 0.02</size>
	  </box>
	</geometry>
      </collision>
    </link>

    <joint name="elbow_joint" type="revolute">
      <parent>shoulder_link</parent>
      <child>elbow_link</child>
      <pose>0 -0.135 0  0 0 0"</pose>
      <axis>
	<xyz>0 1 0</xyz>
	<limit>
	  <lower>-1.919862177</lower>
	  <upper>0.6981317008</upper>
	  <effort>1000</effort>
	  <velocity>1</velocity>
	</limit>
      </axis>
    </joint>


    <link name="roll_link">
      <visual name="roll_visual">
	<geometry>
	  <box>
	    <size>0.03 0.003 0.04</size>
	  </box>
	</geometry>
	<material>
	  <ambient>1 0.81 0.4 1</ambient>
	  <diffuse>1 0.81 0.4 1</diffuse>
	</material>
      </visual>
      <collision name="roll_collision">
	<geometry>
	  <box>
	    <size>0.03 0.003 0.04</size>
	  </box>
	</geometry>
      </collision>
    </link>

    <joint name="roll_joint" type="revolute">
      <parent>elbow_link</parent>
      <child>roll_link</child>
      <pose>0 0.065 0  0 0 0</pose>
      <axis>
	<xyz>0 1 0</xyz>
	<limit>
	  <lower>-1.570796327</lower>
	  <upper>1.570796327</upper>
	  <effort>1000</effort>
	  <velocity>1</velocity>
	</limit>
      </axis>
    </joint>


    <link name="clamp_link">
      <visual name="clamp_visual">
	<pose>0 0.025 0  0 0 0</pose>
	<geometry>
	  <box>
	    <size>0.02 0.05 0.01</size>
	  </box>
	</geometry>
	<material>
	  <ambient>1 0.81 0.4 1</ambient>
	  <diffuse>1 0.81 0.4 1</diffuse>
	</material>
      </visual>
      <collision name="clamp_collision">
	<geometry>
	  <box>
	    <size>0.02 0.05 0.01</size>
	  </box>
	</geometry>
      </collision>
    </link>

    <joint name="clamp_joint" type="revolute">
      <parent>roll_link</parent>
      <child>clamp_link</child>
      <pose>0 0.001 -0.005  0 0 0</pose>
      <axis>
	<xyz>1 0 0</xyz>
	<limit>
	  <lower>0</lower>
	  <upper>0.6981317008</upper>
	  <effort>1000</effort>
	  <velocity>1</velocity>
	</limit>
      </axis>
    </joint>
-->
  </model>
</sdf>
